<?xml version="1.0" ?>
<robot name="mega3" xmlns:xacro="http://www.ros.org/wiki/xacro">

<xacro:include filename="$(find mega3_description)/urdf/materials.xacro" />
<!-- <xacro:include filename="$(find mega3_description)/urdf/mega3.trans" /> -->
<xacro:include filename="$(find mega3_description)/urdf/mega3.gazebo" />

<link name="base_footprint" />

<joint name="base_joint" type="fixed">
  <parent link="base_footprint"/>
  <child link="base_link" />
  <origin xyz="-0.1 0 0" rpy="0 0 -1.5708"/>
</joint>

<link name="base_link">
  <inertial>
    <origin xyz="-0.0001512201285105937 -3.420007213019073e-05 0.08388833658828038" rpy="0 0 0"/>
    <mass value="55.320133808251406"/>
    <inertia ixx="0.615775" iyy="0.27999" izz="0.754884" ixy="0.001269" iyz="-0.005168" ixz="0.00023"/>
  </inertial>
  <visual>
    <origin xyz="0 0 0" rpy="0 0 0"/>
    <geometry>
      <mesh filename="package://mega3_description/meshes/base_link.stl" scale="0.001 0.001 0.001"/>
    </geometry>
    <material name="silver"/>
  </visual>
  <collision>
    <origin xyz="0 0 0" rpy="0 0 0"/>
    <geometry>
      <mesh filename="package://mega3_description/meshes/base_link.stl" scale="0.001 0.001 0.001"/>
    </geometry>
  </collision>
</link>

<link name="left_wheel_1">
  <inertial>
    <origin xyz="-0.033128043580545455 7.067830727208735e-07 1.2241841348126226e-06" rpy="0 0 0"/>
    <mass value="6.011657058706245"/>
    <inertia ixx="0.012936" iyy="0.008099" izz="0.0081" ixy="-0.0" iyz="0.0" ixz="-0.0"/>
  </inertial>
  <visual>
    <origin xyz="0.105 -0.1 -0.07" rpy="0 0 0"/>
    <geometry>
      <mesh filename="package://mega3_description/meshes/left_wheel_1.stl" scale="0.001 0.001 0.001"/>
    </geometry>
    <material name="silver"/>
  </visual>
  <collision>
    <origin xyz="0.105 -0.1 -0.07" rpy="0 0 0"/>
    <geometry>
      <mesh filename="package://mega3_description/meshes/left_wheel_1.stl" scale="0.001 0.001 0.001"/>
    </geometry>
  </collision>
</link>

<link name="right_wheel_1">
  <inertial>
    <origin xyz="0.03312638365523084 7.067463521914785e-07 -1.2241206745616795e-06" rpy="0 0 0"/>
    <mass value="6.011968399456773"/>
    <inertia ixx="0.012936" iyy="0.0081" izz="0.0081" ixy="0.0" iyz="-0.0" ixz="-0.0"/>
  </inertial>
  <visual>
    <origin xyz="-0.105 -0.1 -0.07" rpy="0 0 0"/>
    <geometry>
      <mesh filename="package://mega3_description/meshes/right_wheel_1.stl" scale="0.001 0.001 0.001"/>
    </geometry>
    <material name="silver"/>
  </visual>
  <collision>
    <origin xyz="-0.105 -0.1 -0.07" rpy="0 0 0"/>
    <geometry>
      <mesh filename="package://mega3_description/meshes/right_wheel_1.stl" scale="0.001 0.001 0.001"/>
    </geometry>
  </collision>
</link>

<joint name="left_wheel_joint" type="continuous">
  <origin xyz="-0.105 0.1 0.07" rpy="0 0 0"/>
  <parent link="base_link"/>
  <child link="left_wheel_1"/>
  <axis xyz="-1.0 0.0 0.0"/>
</joint>

<joint name="right_wheel_joint" type="continuous">
  <origin xyz="0.105 0.1 0.07" rpy="0 0 0"/>
  <parent link="base_link"/>
  <child link="right_wheel_1"/>
  <axis xyz="1.0 0.0 0.0"/>
</joint>

</robot>
