<?xml version="1.0" ?>
<robot name="f120a" xmlns:xacro="http://www.ros.org/wiki/xacro">

<xacro:include filename="$(find f120a_description)/urdf/materials.xacro" />
<!-- <xacro:include filename="$(find f120a_description)/urdf/f120a.trans" /> -->
<xacro:include filename="$(find f120a_description)/urdf/f120a.gazebo" />

<link name="base_footprint" />

<joint name="base_joint" type="fixed">
  <parent link="base_footprint"/>
  <child link="base_link" />
  <origin xyz="-0.108 0 0" rpy="0 0 -1.5708"/>
</joint>

<link name="base_link">
  <inertial>
    <origin xyz="6.540114906371634e-07 -0.003250873034356485 0.120269680948673" rpy="0 0 0"/>
    <mass value="79.98438407598134"/>
    <inertia ixx="0.687749" iyy="0.89788" izz="1.3018" ixy="-0.000134" iyz="-0.001694" ixz="9.4e-05"/>
  </inertial>
  <visual>
    <origin xyz="0 0 0" rpy="0 0 0"/>
    <geometry>
      <mesh filename="package://f120a_description/meshes/base_link.stl" scale="0.001 0.001 0.001"/>
    </geometry>
    <material name="silver"/>
  </visual>
  <collision>
    <origin xyz="0 0 0" rpy="0 0 0"/>
    <geometry>
      <mesh filename="package://f120a_description/meshes/base_link.stl" scale="0.001 0.001 0.001"/>
    </geometry>
  </collision>
</link>

<link name="right_wheel_1">
  <inertial>
    <origin xyz="0.03637506015849254 7.02055508131072e-06 -1.1815954602742429e-05" rpy="0 0 0"/>
    <mass value="1.541653423609473"/>
    <inertia ixx="0.03088" iyy="0.018304" izz="0.018305" ixy="3e-06" iyz="0.0" ixz="-4e-06"/>
  </inertial>
  <visual>
    <origin xyz="-0.167 -0.108 -0.085" rpy="0 0 0"/>
    <geometry>
      <mesh filename="package://f120a_description/meshes/right_wheel_1.stl" scale="0.001 0.001 0.001"/>
    </geometry>
    <material name="silver"/>
  </visual>
  <collision>
    <origin xyz="-0.167 -0.108 -0.085" rpy="0 0 0"/>
    <geometry>
      <mesh filename="package://f120a_description/meshes/right_wheel_1.stl" scale="0.001 0.001 0.001"/>
    </geometry>
  </collision>
</link>

<link name="left_wheel_1">
  <inertial>
    <origin xyz="-0.036375060158495454 -2.5558693036720204e-06 -1.3504536612696239e-05" rpy="0 0 0"/>
    <mass value="1.541653423609318"/>
    <inertia ixx="0.03088" iyy="0.018305" izz="0.018304" ixy="2e-06" iyz="-0.0" ixz="5e-06"/>
  </inertial>
  <visual>
    <origin xyz="0.167 -0.108 -0.085" rpy="0 0 0"/>
    <geometry>
      <mesh filename="package://f120a_description/meshes/left_wheel_1.stl" scale="0.001 0.001 0.001"/>
    </geometry>
    <material name="silver"/>
  </visual>
  <collision>
    <origin xyz="0.167 -0.108 -0.085" rpy="0 0 0"/>
    <geometry>
      <mesh filename="package://f120a_description/meshes/left_wheel_1.stl" scale="0.001 0.001 0.001"/>
    </geometry>
  </collision>
</link>

<joint name="right_wheel_joint" type="continuous">
  <origin xyz="0.167 0.108 0.085" rpy="0 0 0"/>
  <parent link="base_link"/>
  <child link="right_wheel_1"/>
  <axis xyz="1.0 0.0 0.0"/>
</joint>

<joint name="left_wheel_joint" type="continuous">
  <origin xyz="-0.167 0.108 0.085" rpy="0 0 0"/>
  <parent link="base_link"/>
  <child link="left_wheel_1"/>
  <axis xyz="1.0 0.0 0.0"/>
</joint>

</robot>
